Workbook

Sheet Каталог
A1: Себестоимость = цветы по прайсу оптовой базы «Прайс_07_07» + упаковка. Упаковка: до 11 стеблей — 90 ₽, 12–25 — 140 ₽, 26–51 — 190 ₽, свыше 51 — 250 ₽ (тариф на листе «Прайс», ячейки G5:G8 — правится там, пересчёт по всему файлу автоматический). Доставка в себестоимость НЕ входит: оплачивается клиентом отдельно через Яндекс.Доставку и на маржу не влияет.
A2: ID | B2: Название | C2: Категория | D2: Состав (вид и кол-во) | E2: Описание | F2: Упаковка, ₽ | G2: Себестоимость | H2: Цена | I2: Маржа ₽ | J2: Маржа % | K2: Сезон/повод | L2: Фото есть | M2: Статус | N2: Примечание
A3: PRD-01 | B3: Бакарди | C3: Стандарт | D3: хризантема кустовая Бакарди белая × 9 | E3: Девять белых кустовых хризантем сорта Бакарди — ромашковая простота без единого лишнего цвета. Хорошо смотрится в стеклянной банке. | F3: =Прайс!$G$5 | G3: =9*Прайс!$D$160+$F3 | H3: 1590 | I3: =IF(ISNUMBER($G3),$H3-$G3,"—") | J3: =IF(ISNUMBER($G3),($H3-$G3)/$H3,"—") | K3: круглый год | L3: да | M3: в каталоге бота | N3: сейчас в боте · категория проставлена по ценовой сетке каталога — подтвердить
A4: PRD-02 | B4: Шар | C4: Стандарт | D4: гвоздика кустовая × 15 | E4: Пятнадцать кустовых гвоздик в плотном ровном шаре. Держит форму неделями и почти не пьёт воду — берут в офис и на ресепшн. | F4: =Прайс!$G$6 | G4: =15*Прайс!$D$34+$F4 | H4: 1790 | I4: =IF(ISNUMBER($G4),$H4-$G4,"—") | J4: =IF(ISNUMBER($G4),($H4-$G4)/$H4,"—") | K4: круглый год | L4: да | M4: в каталоге бота | N4: сейчас в боте · категория проставлена по ценовой сетке каталога — подтвердить · в прайсе также «гвоздика китай кустовая» 39,90 ₽ (01220) — счёт по «Гвоздика Эквадор Кустовая» (00774)
A5: PRD-03 | B5: Лёгкий | C5: Стандарт | D5: альстромерия Краснодар 60 см × 21 | E5: Двадцать одна краснодарская альстромерия: много цветов за небольшие деньги. Раскрывается постепенно, дней десять подряд. | F5: =Прайс!$G$6 | G5: =21*Прайс!$D$245+$F5 | H5: 1990 | I5: =IF(ISNUMBER($G5),$H5-$G5,"—") | J5: =IF(ISNUMBER($G5),($H5-$G5)/$H5,"—") | K5: круглый год | L5: да | M5: в каталоге бота | N5: сейчас в боте · категория проставлена по ценовой сетке каталога — подтвердить
A6: NEW-01 | B6: Мёд | C6: Стандарт | D6: гербера × 9 | E6: Девять крупных гербер тёплого янтарного тона. Простая, почти детская радость — хорошо заходит как букет без повода. | F6: =Прайс!$G$5 | G6: =9*Прайс!$D$36+$F6 | H6: 1090 | I6: =IF(ISNUMBER($G6),$H6-$G6,"—") | J6: =IF(ISNUMBER($G6),($H6-$G6)/$H6,"—") | K6: круглый год | L6: да | M6: новый — завести через /add | N6: новый · состав увеличен с 5 до 9 гербер (5 стеблей давали слишком тонкий букет), цена пересчитана с 1 290 ₽ под маржу около 60%
A7: NEW-02 | B7: Орех | C7: Стандарт | D7: гвоздика пудровая × 9 | E7: Девять пудровых гвоздик приглушённого бежевого тона. Спокойный букет для тех, кто не любит яркое. | F7: =Прайс!$G$5 | G7: =9*Прайс!$D$33+$F7 | H7: 1190 | I7: =IF(ISNUMBER($G7),$H7-$G7,"—") | J7: =IF(ISNUMBER($G7),($H7-$G7)/$H7,"—") | K7: круглый год | L7: да | M7: новый — завести через /add | N7: новый · оттенок «пудровая» в прайсе не выделен — счёт по «гвоздика Эквадор» (00026)
A8: NEW-03 | B8: Штрих | C8: Стандарт | D8: гладиолус × 5 | E8: Пять гладиолусов в рост, строгая вертикаль без единой лишней детали. Там, где нужен жест, а не пышность. | F8: =Прайс!$G$5 | G8: =5*Прайс!$D$40+$F8 | H8: 1290 | I8: =IF(ISNUMBER($G8),$H8-$G8,"—") | J8: =IF(ISNUMBER($G8),($H8-$G8)/$H8,"—") | K8: август–сентябрь | L8: нет | M8: новый — завести через /add | N8: новый
A9: NEW-04 | B9: Воздух | C9: Стандарт | D9: маттиола × 5 | E9: Пять веток маттиолы — тот самый пряно-сладкий запах, который слышно из коридора. Букет-настроение. | F9: =Прайс!$G$5 | G9: =5*Прайс!$D$59+$F9 | H9: 1290 | I9: =IF(ISNUMBER($G9),$H9-$G9,"—") | J9: =IF(ISNUMBER($G9),($H9-$G9)/$H9,"—") | K9: весна–лето | L9: нет | M9: новый — завести через /add | N9: новый
A10: NEW-05 | B10: Клубничный Мусс | C10: Стандарт | D10: роза Кения микс 40 см × 15 | E10: Пятнадцать кенийских роз в розово-ягодном миксе. Лёгкий букет на день рождения подруге или сестре. | F10: =Прайс!$G$6 | G10: =15*Прайс!$D$77+$F10 | H10: 1490 | I10: =IF(ISNUMBER($G10),$H10-$G10,"—") | J10: =IF(ISNUMBER($G10),($H10-$G10)/$H10,"—") | K10: день рождения | L10: да | M10: новый — завести через /add | N10: новый
A11: NEW-06 | B11: Бронза | C11: Стандарт | D11: хризантема кустовая осенняя × 7 | E11: Семь кустовых хризантем в осенней палитре: охра, ржавчина, тёмное золото. Стоит в вазе две недели и не осыпается. | F11: =Прайс!$G$5 | G11: =7*Прайс!$D$122+$F11 | H11: 1590 | I11: =IF(ISNUMBER($G11),$H11-$G11,"—") | J11: =IF(ISNUMBER($G11),($H11-$G11)/$H11,"—") | K11: осень | L11: да | M11: новый — завести через /add | N11: новый · сезонный оттенок в прайсе не выделен — счёт по «Хризантема кустовая Голландия цветная» (00045)
A12: NEW-07 | B12: Мокко | C12: Стандарт | D12: гвоздика кофейных оттенков × 15 | E12: Пятнадцать гвоздик кофейных оттенков — от какао до карамели. Плотная шапка, которая долго держит форму. | F12: =Прайс!$G$6 | G12: =15*Прайс!$D$33+$F12 | H12: 1690 | I12: =IF(ISNUMBER($G12),$H12-$G12,"—") | J12: =IF(ISNUMBER($G12),($H12-$G12)/$H12,"—") | K12: круглый год | L12: да | M12: новый — завести через /add | N12: новый · оттенок «кофейный» в прайсе не выделен — счёт по «гвоздика Эквадор» (00026)
A13: NEW-08 | B13: Фарфор | C13: Стандарт | D13: роза Горкунов белая 50 см × 9 | E13: Девять белых роз Горкунова на пятидесятой ноге. Чистая классика без зелени и лишнего декора. | F13: =Прайс!$G$5 | G13: =9*Прайс!$D$74+$F13 | H13: 1890 | I13: =IF(ISNUMBER($G13),$H13-$G13,"—") | J13: =IF(ISNUMBER($G13),($H13-$G13)/$H13,"—") | K13: круглый год | L13: да | M13: новый — завести через /add | N13: новый · цвет в прайсе не выделен — счёт по «Роза ГОРКУНОВ 50 см одног» (01065)
A14: NEW-09 | B14: Первоклассник | C14: Стандарт | D14: роза Кения красная 40 см × 9, солидаго × 3 | E14: Девять красных роз с солидаго — букет к первому звонку, который не рассыпется по дороге в школу. | F14: =Прайс!$G$6 | G14: =9*Прайс!$D$78+3*Прайс!$D$115+$F14 | H14: 1890 | I14: =IF(ISNUMBER($G14),$H14-$G14,"—") | J14: =IF(ISNUMBER($G14),($H14-$G14)/$H14,"—") | K14: 1 сентября | L14: да | M14: новый — завести через /add | N14: новый · цена поднята с 1590 ₽: с упаковкой (140 ₽) маржа была 49,9% (<50%), новая маржа 57,9%
A15: NEW-10 | B15: Луч | C15: Стандарт | D15: подсолнух × 3, гиперикум × 3 | E15: Три подсолнуха с гроздьями гиперикума — светится даже в пасмурный день. Берут учителю, соседке, маме «просто так». | F15: =Прайс!$G$5 | G15: =3*Прайс!$D$68+3*Прайс!$D$37+$F15 | H15: 1990 | I15: =IF(ISNUMBER($G15),$H15-$G15,"—") | J15: =IF(ISNUMBER($G15),($H15-$G15)/$H15,"—") | K15: конец лета, 1 сентября | L15: да | M15: новый — завести через /add | N15: новый · цена поднята с 1490 ₽: с упаковкой (90 ₽) маржа была 43,7% (<50%), новая маржа 57,8%
A16: NEW-11 | B16: Лиса | C16: Стандарт | D16: георгин × 5 | E16: Пять георгинов с рыжими и медными переливами. Осенний характер: чуть растрёпанный, но собранный. | F16: =Прайс!$G$5 | G16: =5*Прайс!$D$35+$F16 | H16: 1990 | I16: =IF(ISNUMBER($G16),$H16-$G16,"—") | J16: =IF(ISNUMBER($G16),($H16-$G16)/$H16,"—") | K16: осень | L16: да | M16: новый — завести через /add | N16: новый · цена поднята с 1490 ₽: с упаковкой (90 ₽) маржа была 43,6% (<50%), новая маржа 57,8% · в прайсе также «Георгин Китай» 99,90 ₽ (01296) — счёт по основной позиции «Георгина» (01018)
A17: NEW-12 | B17: Рубиновый Закат | C17: Стандарт | D17: роза Кения красная 40 см × 21 | E17: Двадцать одна красная кенийская роза плотной сборкой. Недорогой способ сказать серьёзное. | F17: =Прайс!$G$6 | G17: =21*Прайс!$D$78+$F17 | H17: 1990 | I17: =IF(ISNUMBER($G17),$H17-$G17,"—") | J17: =IF(ISNUMBER($G17),($H17-$G17)/$H17,"—") | K17: свидание, годовщина | L17: да | M17: новый — завести через /add | N17: новый
A18: PRD-04 | B18: Солнце | C18: Премиум | D18: подсолнух × 9 | E18: Девять подсолнухов без зелени и упаковки. Прямолинейный букет — его нельзя перепутать ни с чем и не нужно объяснять. | F18: =Прайс!$G$5 | G18: =9*Прайс!$D$68+$F18 | H18: 3690 | I18: =IF(ISNUMBER($G18),$H18-$G18,"—") | J18: =IF(ISNUMBER($G18),($H18-$G18)/$H18,"—") | K18: лето–осень | L18: да | M18: в каталоге бота | N18: сейчас в боте · категория проставлена по ценовой сетке каталога — подтвердить · цена живая, в боте стоит 2790 ₽ — обновить через /edit · цена поднята с 2790 ₽: с упаковкой (90 ₽) маржа была 45,2% (<50%), новая маржа 58,6%
A19: PRD-05 | B19: Антуриум | C19: Премиум | D19: антуриум срезка × 7 | E19: Семь срезанных антуриумов: глянцевые лаковые покрывала, ничего лишнего. Для тех, кому не нужны лепестки. | F19: =Прайс!$G$5 | G19: =7*Прайс!$D$2+$F19 | H19: 3990 | I19: =IF(ISNUMBER($G19),$H19-$G19,"—") | J19: =IF(ISNUMBER($G19),($H19-$G19)/$H19,"—") | K19: мужчине, новоселье | L19: да | M19: в каталоге бота | N19: сейчас в боте · категория проставлена по ценовой сетке каталога — подтвердить
A20: PRD-06 | B20: Пионовидный сад | C20: Премиум | D20: роза Эквадор пионовидная 60 см × 15 | E20: Пятнадцать эквадорских пионовидных роз на шестидесятой ноге. Плотные тяжёлые головы, которые раскрываются в чашу. | F20: =Прайс!$G$6 | G20: =15*Прайс!$D$97+$F20 | H20: 4290 | I20: =IF(ISNUMBER($G20),$H20-$G20,"—") | J20: =IF(ISNUMBER($G20),($H20-$G20)/$H20,"—") | K20: свадьба, годовщина | L20: да | M20: в каталоге бота | N20: сейчас в боте · категория проставлена по ценовой сетке каталога — подтвердить · в прайсе позиция называется «Роза Эквадор Пионовидная + Сорт 60 см» (00673) — отдельной «чисто пионовидной» нет
A21: PRD-07 | B21: Густой август | C21: Премиум | D21: подсолнух × 7, гиперикум × 3, эвкалипт × 1 | E21: Семь подсолнухов, гиперикум и ветка эвкалипта — тёплый, чуть пыльный августовский букет. Пахнет концом лета. | F21: =Прайс!$G$5 | G21: =7*Прайс!$D$68+3*Прайс!$D$37+1*Прайс!$D$140+$F21 | H21: 4490 | I21: =IF(ISNUMBER($G21),$H21-$G21,"—") | J21: =IF(ISNUMBER($G21),($H21-$G21)/$H21,"—") | K21: август, 1 сентября | L21: да | M21: в каталоге бота | N21: сейчас в боте · категория проставлена по ценовой сетке каталога — подтвердить · цена живая, в боте стоит 3690 ₽ — обновить через /edit · цена поднята с 3690 ₽: с упаковкой (90 ₽) маржа была 49,3% (<50%), новая маржа 58,4% · в прайсе «эвкалипт» 390 ₽ (00350) без указания фасовки (шт/пучок) — счёт как за штуку
A22: PRD-08 | B22: Эустома | C22: Премиум | D22: эустома PREMIUM × 11 | E22: Одиннадцать веток эустомы PREMIUM — крупные бутоны на длинной ноге. Монобукет, который выглядит дороже своей цены. | F22: =Прайс!$G$5 | G22: =11*Прайс!$D$159+$F22 | H22: 4690 | I22: =IF(ISNUMBER($G22),$H22-$G22,"—") | J22: =IF(ISNUMBER($G22),($H22-$G22)/$H22,"—") | K22: круглый год | L22: да | M22: в каталоге бота | N22: сейчас в боте · категория проставлена по ценовой сетке каталога — подтвердить · цена живая, в боте стоит 3290 ₽ — обновить через /edit · цена поднята с 3290 ₽: с упаковкой (90 ₽) маржа была 40,5% (<50%), новая маржа 58,2%
A23: PRD-09 | B23: Тотал ред | C23: Премиум | D23: роза Ред Наоми 60 см × 25 | E23: Двадцать пять роз Ред Наоми на шестидесятой ноге: тёмный бархатный красный, который на фото выглядит почти чёрным. | F23: =Прайс!$G$6 | G23: =25*Прайс!$D$299+$F23 | H23: 4990 | I23: =IF(ISNUMBER($G23),$H23-$G23,"—") | J23: =IF(ISNUMBER($G23),($H23-$G23)/$H23,"—") | K23: свидание, годовщина | L23: да | M23: в каталоге бота | N23: сейчас в боте · категория проставлена по ценовой сетке каталога — подтвердить · в прайсе две позиции «Ред Наоми 60 см»: Горкунов 87,90 ₽ (01461) и Флорентика 81,00 ₽ (01412) — счёт по Горкунову
A24: NEW-13 | B24: Азбука | C24: Премиум | D24: хризантема кустовая Бакарди белая × 7, гиперикум × 3 | E24: Белая кустовая хризантема с гиперикумом — сдержанный светлый букет для классного руководителя. | F24: =Прайс!$G$5 | G24: =7*Прайс!$D$160+3*Прайс!$D$37+$F24 | H24: 2190 | I24: =IF(ISNUMBER($G24),$H24-$G24,"—") | J24: =IF(ISNUMBER($G24),($H24-$G24)/$H24,"—") | K24: 1 сентября | L24: нет | M24: новый — завести через /add | N24: новый · блок «1 сентября»
A25: NEW-14 | B25: Пенал | C25: Премиум | D25: гербера × 9, гиперикум × 4 | E25: Девять гербер и гиперикум — яркий и крепкий, не боится дороги до школы. Собирается за пять минут. | F25: =Прайс!$G$6 | G25: =9*Прайс!$D$36+4*Прайс!$D$37+$F25 | H25: 2290 | I25: =IF(ISNUMBER($G25),$H25-$G25,"—") | J25: =IF(ISNUMBER($G25),($H25-$G25)/$H25,"—") | K25: 1 сентября | L25: нет | M25: новый — завести через /add | N25: новый · блок «1 сентября»
A26: NEW-15 | B26: Линейка | C26: Премиум | D26: гвоздика микс × 15, солидаго × 3 | E26: Пятнадцать гвоздик с солидаго — плотный купол в школьных красно-жёлтых тонах. | F26: =Прайс!$G$6 | G26: =15*Прайс!$D$33+3*Прайс!$D$115+$F26 | H26: 2290 | I26: =IF(ISNUMBER($G26),$H26-$G26,"—") | J26: =IF(ISNUMBER($G26),($H26-$G26)/$H26,"—") | K26: 1 сентября | L26: нет | M26: новый — завести через /add | N26: новый · блок «1 сентября» · микс в прайсе не выделен — счёт по «гвоздика Эквадор» (00026)
A27: NEW-16 | B27: Перемена | C27: Премиум | D27: гладиолус × 7, хризантема кустовая цветная × 3 | E27: Семь гладиолусов с кустовой хризантемой — высокий букет для линейки, видно с последнего ряда. | F27: =Прайс!$G$5 | G27: =7*Прайс!$D$40+3*Прайс!$D$122+$F27 | H27: 2390 | I27: =IF(ISNUMBER($G27),$H27-$G27,"—") | J27: =IF(ISNUMBER($G27),($H27-$G27)/$H27,"—") | K27: 1 сентября | L27: нет | M27: новый — завести через /add | N27: новый · блок «1 сентября»
A28: NEW-17 | B28: Ранец | C28: Премиум | D28: гладиолус × 5, гербера × 5, солидаго × 2 | E28: Гладиолусы, герберы и солидаго — крепкая конструкция, которую можно везти в машине лёжа. | F28: =Прайс!$G$6 | G28: =5*Прайс!$D$40+5*Прайс!$D$36+2*Прайс!$D$115+$F28 | H28: 2390 | I28: =IF(ISNUMBER($G28),$H28-$G28,"—") | J28: =IF(ISNUMBER($G28),($H28-$G28)/$H28,"—") | K28: 1 сентября | L28: нет | M28: новый — завести через /add | N28: новый · блок «1 сентября»
A29: NEW-18 | B29: Звонок | C29: Премиум | D29: гладиолус × 11 | E29: Одиннадцать гладиолусов: высокий торжественный букет для линейки и сцены. Виден из последнего ряда. | F29: =Прайс!$G$5 | G29: =11*Прайс!$D$40+$F29 | H29: 2490 | I29: =IF(ISNUMBER($G29),$H29-$G29,"—") | J29: =IF(ISNUMBER($G29),($H29-$G29)/$H29,"—") | K29: 1 сентября, юбилей | L29: да | M29: новый — завести через /add | N29: новый
A30: NEW-19 | B30: Глобус | C30: Премиум | D30: хризантема кустовая цветная × 9, солидаго × 3 | E30: Кустовая хризантема с солидаго: пушистый жёлто-зелёный шар, который простоит на учительском столе две недели. | F30: =Прайс!$G$6 | G30: =9*Прайс!$D$122+3*Прайс!$D$115+$F30 | H30: 2490 | I30: =IF(ISNUMBER($G30),$H30-$G30,"—") | J30: =IF(ISNUMBER($G30),($H30-$G30)/$H30,"—") | K30: 1 сентября | L30: нет | M30: новый — завести через /add | N30: новый · блок «1 сентября»
A31: NEW-20 | B31: Мелок | C31: Премиум | D31: альстромерия Эквадор 60 см × 11, хризантема кустовая цветная × 3 | E31: Одиннадцать альстромерий с кустовой хризантемой. Самый стойкий вариант на 1 сентября: доживёт до октября. | F31: =Прайс!$G$6 | G31: =11*Прайс!$D$315+3*Прайс!$D$122+$F31 | H31: 2490 | I31: =IF(ISNUMBER($G31),$H31-$G31,"—") | J31: =IF(ISNUMBER($G31),($H31-$G31)/$H31,"—") | K31: 1 сентября | L31: нет | M31: новый — завести через /add | N31: новый · блок «1 сентября»
A32: NEW-21 | B32: Циркуль | C32: Премиум | D32: гербера × 5, альстромерия Эквадор 60 см × 7, гиперикум × 3 | E32: Гербера, альстромерия и гиперикум: компактный букет, который первокласснику удобно нести самому. | F32: =Прайс!$G$6 | G32: =5*Прайс!$D$36+7*Прайс!$D$315+3*Прайс!$D$37+$F32 | H32: 2590 | I32: =IF(ISNUMBER($G32),$H32-$G32,"—") | J32: =IF(ISNUMBER($G32),($H32-$G32)/$H32,"—") | K32: 1 сентября | L32: нет | M32: новый — завести через /add | N32: новый · блок «1 сентября»
A33: NEW-22 | B33: Эустома Мусс | C33: Премиум | D33: эустома × 7 | E33: Семь веток обычной эустомы — пастельное облако из множества некрупных бутонов. Раскрывается ещё три дня после доставки. | F33: =Прайс!$G$5 | G33: =7*Прайс!$D$162+$F33 | H33: 2690 | I33: =IF(ISNUMBER($G33),$H33-$G33,"—") | J33: =IF(ISNUMBER($G33),($H33-$G33)/$H33,"—") | K33: круглый год | L33: да | M33: новый — завести через /add | N33: новый · переименован из «Мусс», чтобы не путался с «Клубничный Мусс»; фото заведено под прежним названием
A34: NEW-23 | B34: Сентябрь | C34: Премиум | D34: гербера × 5, хризантема кустовая цветная × 5, гладиолус × 3, солидаго × 2 | E34: Гербера, хризантема, гладиолус и солидаго: четыре вида в тёплой охристой гамме, самый «сентябрьский» из набора. | F34: =Прайс!$G$6 | G34: =5*Прайс!$D$36+5*Прайс!$D$122+3*Прайс!$D$40+2*Прайс!$D$115+$F34 | H34: 2790 | I34: =IF(ISNUMBER($G34),$H34-$G34,"—") | J34: =IF(ISNUMBER($G34),($H34-$G34)/$H34,"—") | K34: 1 сентября | L34: нет | M34: новый — завести через /add | N34: новый · блок «1 сентября»
A35: NEW-24 | B35: Астра | C35: Премиум | D35: гвоздика микс × 25 | E35: Двадцать пять гвоздик в миксе — плотный купол из ярких головок. Отлично держится в дороге и на жаре. | F35: =Прайс!$G$6 | G35: =25*Прайс!$D$33+$F35 | H35: 2890 | I35: =IF(ISNUMBER($G35),$H35-$G35,"—") | J35: =IF(ISNUMBER($G35),($H35-$G35)/$H35,"—") | K35: 1 сентября, выпускной | L35: да | M35: новый — завести через /add | N35: новый · микс в прайсе не выделен — счёт по «гвоздика Эквадор» (00026)
A36: NEW-25 | B36: Специя | C36: Премиум | D36: роза Горкунов красная 50 см × 9, гиперикум × 5 | E36: Девять красных роз Горкунова с гиперикумом: глубокий цвет и ягодные акценты вместо привычной зелени. | F36: =Прайс!$G$6 | G36: =9*Прайс!$D$74+5*Прайс!$D$37+$F36 | H36: 2990 | I36: =IF(ISNUMBER($G36),$H36-$G36,"—") | J36: =IF(ISNUMBER($G36),($H36-$G36)/$H36,"—") | K36: свидание | L36: да | M36: новый — завести через /add | N36: новый · цвет в прайсе не выделен — счёт по «Роза ГОРКУНОВ 50 см одног» (01065)
A37: NEW-26 | B37: Тоффи | C37: Премиум | D37: альстромерия Эквадор 60 см × 15 | E37: Пятнадцать эквадорских альстромерий карамельных оттенков. Один из самых стойких букетов в каталоге. | F37: =Прайс!$G$6 | G37: =15*Прайс!$D$315+$F37 | H37: 3290 | I37: =IF(ISNUMBER($G37),$H37-$G37,"—") | J37: =IF(ISNUMBER($G37),($H37-$G37)/$H37,"—") | K37: круглый год | L37: да | M37: новый — завести через /add | N37: новый
A38: NEW-27 | B38: Инжир | C38: Премиум | D38: гербера микс × 15, гиперикум × 5 | E38: Пятнадцать гербер в миксе тёплых тонов, подсвеченных гиперикумом. Крупный и щедрый, без пафоса. | F38: =Прайс!$G$6 | G38: =15*Прайс!$D$36+5*Прайс!$D$37+$F38 | H38: 3490 | I38: =IF(ISNUMBER($G38),$H38-$G38,"—") | J38: =IF(ISNUMBER($G38),($H38-$G38)/$H38,"—") | K38: осень, 1 сентября | L38: да | M38: новый — завести через /add | N38: новый · микс в прайсе не выделен — счёт по «гербера армения» (00448)
A39: NEW-28 | B39: Кобальт | C39: Премиум | D39: роза Эквадор синяя 40 см × 11 | E39: Одиннадцать синих эквадорских роз — редкий цвет, который запоминают. Подарок с характером. | F39: =Прайс!$G$5 | G39: =11*Прайс!$D$83+$F39 | H39: 3490 | I39: =IF(ISNUMBER($G39),$H39-$G39,"—") | J39: =IF(ISNUMBER($G39),($H39-$G39)/$H39,"—") | K39: день рождения | L39: да | M39: новый — завести через /add | N39: новый
A40: NEW-29 | B40: Снежный Мел | C40: Премиум | D40: роза Горкунов белая 50 см × 25 | E40: Двадцать пять белых роз на пятидесятой ноге. Строгая монобукетная классика для важных дат. | F40: =Прайс!$G$6 | G40: =25*Прайс!$D$74+$F40 | H40: 3990 | I40: =IF(ISNUMBER($G40),$H40-$G40,"—") | J40: =IF(ISNUMBER($G40),($H40-$G40)/$H40,"—") | K40: свадьба, годовщина | L40: да | M40: новый — завести через /add | N40: новый · цвет в прайсе не выделен — счёт по «Роза ГОРКУНОВ 50 см одног» (01065)
...

Sheet 1 сентября
A1: Блок «1 сентября». Все цифры — ссылки на лист «Каталог», отдельно ничего не правится. Себестоимость включает упаковку; доставка оплачивается клиентом отдельно.
A2: ID | B2: Название | C2: Категория | D2: Состав | E2: Описание | F2: Себестоимость | G2: Цена | H2: Маржа ₽ | I2: Маржа % | J2: Пометка | K2: Комментарий
A3: =Каталог!$A$14 | B3: =Каталог!$B$14 | C3: =Каталог!$C$14 | D3: =Каталог!$D$14 | E3: =Каталог!$E$14 | F3: =Каталог!$G$14 | G3: =Каталог!$H$14 | H3: =IF(ISNUMBER($F3),$G3-$F3,"—") | I3: =IF(ISNUMBER($F3),($G3-$F3)/$G3,"—") | J3: из каталога | K3: красные розы + солидаго, классика первого звонка
A4: =Каталог!$A$29 | B4: =Каталог!$B$29 | C4: =Каталог!$C$29 | D4: =Каталог!$D$29 | E4: =Каталог!$E$29 | F4: =Каталог!$G$29 | G4: =Каталог!$H$29 | H4: =IF(ISNUMBER($F4),$G4-$F4,"—") | I4: =IF(ISNUMBER($F4),($G4-$F4)/$G4,"—") | J4: из каталога | K4: ростовой букет для линейки
A5: =Каталог!$A$15 | B5: =Каталог!$B$15 | C5: =Каталог!$C$15 | D5: =Каталог!$D$15 | E5: =Каталог!$E$15 | F5: =Каталог!$G$15 | G5: =Каталог!$H$15 | H5: =IF(ISNUMBER($F5),$G5-$F5,"—") | I5: =IF(ISNUMBER($F5),($G5-$F5)/$G5,"—") | J5: из каталога | K5: подсолнухи — самый «сентябрьский» цветок
A6: =Каталог!$A$52 | B6: =Каталог!$B$52 | C6: =Каталог!$C$52 | D6: =Каталог!$D$52 | E6: =Каталог!$E$52 | F6: =Каталог!$G$52 | G6: =Каталог!$H$52 | H6: =IF(ISNUMBER($F6),$G6-$F6,"—") | I6: =IF(ISNUMBER($F6),($G6-$F6)/$G6,"—") | J6: из каталога | K6: подсолнухи охапкой, для директора/завуча
A7: =Каталог!$A$55 | B7: =Каталог!$B$55 | C7: =Каталог!$C$55 | D7: =Каталог!$D$55 | E7: =Каталог!$E$55 | F7: =Каталог!$G$55 | G7: =Каталог!$H$55 | H7: =IF(ISNUMBER($F7),$G7-$F7,"—") | I7: =IF(ISNUMBER($F7),($G7-$F7)/$G7,"—") | J7: из каталога | K7: осенний люкс, подарок от класса
A8: =Каталог!$A$35 | B8: =Каталог!$B$35 | C8: =Каталог!$C$35 | D8: =Каталог!$D$35 | E8: =Каталог!$E$35 | F8: =Каталог!$G$35 | G8: =Каталог!$H$35 | H8: =IF(ISNUMBER($F8),$G8-$F8,"—") | I8: =IF(ISNUMBER($F8),($G8-$F8)/$G8,"—") | J8: из каталога | K8: гвоздика микс, стойкая на жаре
A9: =Каталог!$A$38 | B9: =Каталог!$B$38 | C9: =Каталог!$C$38 | D9: =Каталог!$D$38 | E9: =Каталог!$E$38 | F9: =Каталог!$G$38 | G9: =Каталог!$H$38 | H9: =IF(ISNUMBER($F9),$G9-$F9,"—") | I9: =IF(ISNUMBER($F9),($G9-$F9)/$G9,"—") | J9: из каталога | K9: герберы, крупный и щедрый
A10: =Каталог!$A$41 | B10: =Каталог!$B$41 | C10: =Каталог!$C$41 | D10: =Каталог!$D$41 | E10: =Каталог!$E$41 | F10: =Каталог!$G$41 | G10: =Каталог!$H$41 | H10: =IF(ISNUMBER($F10),$G10-$F10,"—") | I10: =IF(ISNUMBER($F10),($G10-$F10)/$G10,"—") | J10: из каталога | K10: георгины + астильба, тёплая осенняя гамма
A11: =Каталог!$A$25 | B11: =Каталог!$B$25 | C11: =Каталог!$C$25 | D11: =Каталог!$D$25 | E11: =Каталог!$E$25 | F11: =Каталог!$G$25 | G11: =Каталог!$H$25 | H11: =IF(ISNUMBER($F11),$G11-$F11,"—") | I11: =IF(ISNUMBER($F11),($G11-$F11)/$G11,"—") | J11: новый | K11: сборка спиралью, 5–7 минут, до 4 видов
A12: =Каталог!$A$30 | B12: =Каталог!$B$30 | C12: =Каталог!$C$30 | D12: =Каталог!$D$30 | E12: =Каталог!$E$30 | F12: =Каталог!$G$30 | G12: =Каталог!$H$30 | H12: =IF(ISNUMBER($F12),$G12-$F12,"—") | I12: =IF(ISNUMBER($F12),($G12-$F12)/$G12,"—") | J12: новый | K12: сборка спиралью, 5–7 минут, до 4 видов
A13: =Каталог!$A$27 | B13: =Каталог!$B$27 | C13: =Каталог!$C$27 | D13: =Каталог!$D$27 | E13: =Каталог!$E$27 | F13: =Каталог!$G$27 | G13: =Каталог!$H$27 | H13: =IF(ISNUMBER($F13),$G13-$F13,"—") | I13: =IF(ISNUMBER($F13),($G13-$F13)/$G13,"—") | J13: новый | K13: сборка спиралью, 5–7 минут, до 4 видов
A14: =Каталог!$A$31 | B14: =Каталог!$B$31 | C14: =Каталог!$C$31 | D14: =Каталог!$D$31 | E14: =Каталог!$E$31 | F14: =Каталог!$G$31 | G14: =Каталог!$H$31 | H14: =IF(ISNUMBER($F14),$G14-$F14,"—") | I14: =IF(ISNUMBER($F14),($G14-$F14)/$G14,"—") | J14: новый | K14: сборка спиралью, 5–7 минут, до 4 видов
A15: =Каталог!$A$26 | B15: =Каталог!$B$26 | C15: =Каталог!$C$26 | D15: =Каталог!$D$26 | E15: =Каталог!$E$26 | F15: =Каталог!$G$26 | G15: =Каталог!$H$26 | H15: =IF(ISNUMBER($F15),$G15-$F15,"—") | I15: =IF(ISNUMBER($F15),($G15-$F15)/$G15,"—") | J15: новый | K15: сборка спиралью, 5–7 минут, до 4 видов
A16: =Каталог!$A$32 | B16: =Каталог!$B$32 | C16: =Каталог!$C$32 | D16: =Каталог!$D$32 | E16: =Каталог!$E$32 | F16: =Каталог!$G$32 | G16: =Каталог!$H$32 | H16: =IF(ISNUMBER($F16),$G16-$F16,"—") | I16: =IF(ISNUMBER($F16),($G16-$F16)/$G16,"—") | J16: новый | K16: сборка спиралью, 5–7 минут, до 4 видов
A17: =Каталог!$A$24 | B17: =Каталог!$B$24 | C17: =Каталог!$C$24 | D17: =Каталог!$D$24 | E17: =Каталог!$E$24 | F17: =Каталог!$G$24 | G17: =Каталог!$H$24 | H17: =IF(ISNUMBER($F17),$G17-$F17,"—") | I17: =IF(ISNUMBER($F17),($G17-$F17)/$G17,"—") | J17: новый | K17: сборка спиралью, 5–7 минут, до 4 видов
A18: =Каталог!$A$28 | B18: =Каталог!$B$28 | C18: =Каталог!$C$28 | D18: =Каталог!$D$28 | E18: =Каталог!$E$28 | F18: =Каталог!$G$28 | G18: =Каталог!$H$28 | H18: =IF(ISNUMBER($F18),$G18-$F18,"—") | I18: =IF(ISNUMBER($F18),($G18-$F18)/$G18,"—") | J18: новый | K18: сборка спиралью, 5–7 минут, до 4 видов
A19: =Каталог!$A$34 | B19: =Каталог!$B$34 | C19: =Каталог!$C$34 | D19: =Каталог!$D$34 | E19: =Каталог!$E$34 | F19: =Каталог!$G$34 | G19: =Каталог!$H$34 | H19: =IF(ISNUMBER($F19),$G19-$F19,"—") | I19: =IF(ISNUMBER($F19),($G19-$F19)/$G19,"—") | J19: новый | K19: сборка спиралью, 5–7 минут, до 4 видов

Sheet План выкладки
A1: Порядок вывода каталога в бот. Сегодня 11 августа; пик школьного спроса — 25 августа – 1 сентября. Волна 1 закрывает школу и старт осени, волна 2 — свадьбы, волна 3 — круглогодичная база, которую незачем выкладывать в школьный пик.
A2: Волна | B2: Срок | C2: Почему так | D2: ID | E2: Название | F2: Категория | G2: Цена | H2: Фото | I2: Что сделать до выкладки
A3: 1 | B3: до 18 августа | C3: школьный блок и старт осени — пик спроса 25 августа – 1 сентября | D3: NEW-03 | E3: Штрих | F3: Стандарт | G3: 1290 | H3: нет | I3: снять фото, затем /add
A4: 1 | B4: до 18 августа | C4: школьный блок и старт осени — пик спроса 25 августа – 1 сентября | D4: NEW-06 | E4: Бронза | F4: Стандарт | G4: 1590 | H4: да | I4: фото есть — завести через /add
A5: 1 | B5: до 18 августа | C5: школьный блок и старт осени — пик спроса 25 августа – 1 сентября | D5: NEW-09 | E5: Первоклассник | F5: Стандарт | G5: 1890 | H5: да | I5: фото есть — завести через /add
A6: 1 | B6: до 18 августа | C6: школьный блок и старт осени — пик спроса 25 августа – 1 сентября | D6: NEW-10 | E6: Луч | F6: Стандарт | G6: 1990 | H6: да | I6: фото есть — завести через /add
A7: 1 | B7: до 18 августа | C7: школьный блок и старт осени — пик спроса 25 августа – 1 сентября | D7: NEW-11 | E7: Лиса | F7: Стандарт | G7: 1990 | H7: да | I7: фото есть — завести через /add
A8: 1 | B8: до 18 августа | C8: школьный блок и старт осени — пик спроса 25 августа – 1 сентября | D8: NEW-13 | E8: Азбука | F8: Премиум | G8: 2190 | H8: нет | I8: снять фото, затем /add
A9: 1 | B9: до 18 августа | C9: школьный блок и старт осени — пик спроса 25 августа – 1 сентября | D9: NEW-14 | E9: Пенал | F9: Премиум | G9: 2290 | H9: нет | I9: снять фото, затем /add
A10: 1 | B10: до 18 августа | C10: школьный блок и старт осени — пик спроса 25 августа – 1 сентября | D10: NEW-15 | E10: Линейка | F10: Премиум | G10: 2290 | H10: нет | I10: снять фото, затем /add
A11: 1 | B11: до 18 августа | C11: школьный блок и старт осени — пик спроса 25 августа – 1 сентября | D11: NEW-16 | E11: Перемена | F11: Премиум | G11: 2390 | H11: нет | I11: снять фото, затем /add
A12: 1 | B12: до 18 августа | C12: школьный блок и старт осени — пик спроса 25 августа – 1 сентября | D12: NEW-17 | E12: Ранец | F12: Премиум | G12: 2390 | H12: нет | I12: снять фото, затем /add
A13: 1 | B13: до 18 августа | C13: школьный блок и старт осени — пик спроса 25 августа – 1 сентября | D13: NEW-18 | E13: Звонок | F13: Премиум | G13: 2490 | H13: да | I13: фото есть — завести через /add
A14: 1 | B14: до 18 августа | C14: школьный блок и старт осени — пик спроса 25 августа – 1 сентября | D14: NEW-19 | E14: Глобус | F14: Премиум | G14: 2490 | H14: нет | I14: снять фото, затем /add
... A62: 3 | B62: со 2 сентября | C62: круглогодичная база — вне школьного пика | D62: NEW-45 | E62: Корона 101 | F62: ВАУ | G62: 14990 | H62: да | I62: фото есть — завести через /add

Sheet Прайс
A1: Раздел | B1: Код | C1: Наименование | D1: Опт-цена, ₽ | F1: Копия прайса оптовой базы «Прайс_07_07» — единственный источник закупочных цен.
B2: 00366 | C2: Антуриум срезка | D2: 250 | F2: На эти ячейки ссылаются формулы себестоимости в листах «Каталог» и «1 сентября».
B3: 01043 | C3: роза голландия одноголовая пионовидная*** | D3: 129.9
B4: 01072 | C4: Роза ГОРКУНОВ 40 см КУСТ*** | D4: 129.9 | F4: Упаковка — тариф по числу стеблей
B5: 01266 | C5: виборнум Китай*** | D5: 99.9 | F5: до 11 стеблей | G5: 90
B6: 01267 | C6: оксипиталум Китай*** | D6: 390 | F6: 12–25 стеблей | G6: 140
B7: 01265 | C7: маттиола Китай*** | D7: 49.9 | F7: 26–51 стебель | G7: 190
B8: 01288 | C8: Вриезия | D8: 890 | F8: свыше 51 стебля | G8: 250
B9: 01292 | C9: Фритиллярия | D9: 89.9 | F9: Доставка в себестоимость не входит (Яндекс.Доставка, платит клиент).
B10: 01293 | C10: Вероника Китай*** | D10: 49.9
B11: 01295 | C11: Орнитогалум Китай*** | D11: 89.9
B12: 01296 | C12: Георгин Китай*** | D12: 99.9
B13: 01297 | C13: Фритиллярия Китай *** | D13: 89.9
B14: 01346 | C14: Маттиола КРАСНОДАР *** | D14: 110
B15: 01489 | C15: Оазис Oasis Classic*** | D15: 79.9
A16: цветы срезка | B16: 00980 | C16: Чех Сад кустовая 40см*** | D16: 76.9
A17: цветы срезка | B17: 00982 | C17: Чех сад кустовая 60см*** | D17: 103.9
A18: цветы срезка | B18: 01256 | C18: пион Китай *** | D18: 149.9
A19: цветы срезка | B19: 00404 | C19: Агапантус*** | D19: 129.9
A20: цветы срезка | B20: 01100 | C20: Агератум срез*** | D20: 79.9
A21: цветы срезка | B21: 00654 | C21: Аллиум*** | D21: 109.9
A22: цветы срезка | B22: 00058 | C22: Альстромерия КРАСНОДАР , Армения 80 см*** | D22: 59.9
A23: цветы срезка | B23: 00346 | C23: Амариллис*** | D23: 249.9
A24: цветы срезка | B24: 00532 | C24: анемон*** | D24: 189.9
A25: цветы срезка | B25: 01098 | C25: Арбутус*** | D25: 49.9
A26: цветы срезка | B26: 00963 | C26: Аспедистра*** | D26: 49.9
A27: цветы срезка | B27: 00436 | C27: астильба*** | D27: 89.9
... A569: вазы стекло | B569: 00692 | C569: Ваза стекло фино д7.5х30см | D569: 400

Sheet Сводка
A1: FLOWIX — сводка по каталогу
A2: Себестоимость = цветы по прайсу оптовой базы «Прайс_07_07» + упаковка. Упаковка: до 11 стеблей — 90 ₽, 12–25 — 140 ₽, 26–51 — 190 ₽, свыше 51 — 250 ₽ (тариф на листе «Прайс», ячейки G5:G8 — правится там, пересчёт по всему файлу автоматический). Доставка в себестоимость НЕ входит: оплачивается клиентом отдельно через Яндекс.Доставку и на маржу не влияет.
A4: Всего позиций в каталоге | B4: =COUNTA(Каталог!A3:A62) | C4: строки листа «Каталог»
A5: — из них уже в боте | B5: =COUNTIF(Каталог!A3:A62,"PRD-*") | C5: заведены через /add
A6: — из них новых | B6: =COUNTIF(Каталог!A3:A62,"NEW-*") | C6: список заказчика + блок «1 сентября»
A8: Стандарт | B8: =COUNTIF(Каталог!C3:C62,"Стандарт")
A9: Премиум | B9: =COUNTIF(Каталог!C3:C62,"Премиум")
A10: Люкс | B10: =COUNTIF(Каталог!C3:C62,"Люкс")
A11: ВАУ | B11: =COUNTIF(Каталог!C3:C62,"ВАУ")
A13: Средняя цена | B13: =AVERAGE(Каталог!H3:H62) | C13: ₽
A14: Минимальная цена | B14: =MIN(Каталог!H3:H62) | C14: ₽
A15: Максимальная цена | B15: =MAX(Каталог!H3:H62) | C15: ₽
A16: Средняя себестоимость | B16: =AVERAGE(Каталог!G3:G62) | C16: цветы + упаковка
A17: Расходы на упаковку, всего | B17: =SUM(Каталог!F3:F62) | C17: если собрать по одному букету каждого вида
A18: Средняя маржа % | B18: =AVERAGE(Каталог!J3:J62) | C18: после включения упаковки
A19: Минимальная маржа % | B19: =MIN(Каталог!J3:J62)
A20: Максимальная маржа % | B20: =MAX(Каталог!J3:J62)
A22: Позиций с фото | B22: =COUNTIF(Каталог!L3:L62,"да")
A23: Позиций без фото | B23: =COUNTIF(Каталог!L3:L62,"нет") | C23: списком — в «Проверке» и «Плане выкладки»
A24: Позиций без себестоимости | B24: =COUNTIF(Каталог!G3:G62,"—") | C24: весь состав нашёлся в прайсе
A25: Позиций с маржой ниже 50% | B25: =COUNTIF(Каталог!J3:J62,"<0.5") | C25: после подъёма цен должно быть 0
A26: Позиций с маржой выше 75% | B26: =COUNTIF(Каталог!J3:J62,">0.75")
A27: Позиций дешевле себестоимости | B27: =SUMPRODUCT(--(Каталог!H3:H62<Каталог!G3:G62))
A28: Позиций с поднятой ценой | B28: =COUNTIF(Каталог!N3:N62,"*цена поднята*") | C28: изменения помечены в примечании
A30: Позиций в блоке «1 сентября» | B30: =COUNTA('1 сентября'!A3:A19)
A31: — перенесено из каталога | B31: =COUNTIF('1 сентября'!J3:J19,"из каталога")
A32: — новых | B32: =COUNTIF('1 сентября'!J3:J19,"новый")
A34: Волна 1 — до 18 августа | B34: =COUNTIF('План выкладки'!A3:A62,1) | C34: школа и старт осени
A35: Волна 2 — 19–25 августа | B35: =COUNTIF('План выкладки'!A3:A62,2) | C35: свадьбы и осенний люкс
A36: Волна 3 — со 2 сентября | B36: =COUNTIF('План выкладки'!A3:A62,3) | C36: круглогодичная база
A37: Нужно отснять к волне 1 | B37: =COUNTIFS('План выкладки'!A3:A62,1,'План выкладки'!H3:H62,"нет") | C37: критический путь

Sheet Проверка
A1: # | B1: Тип проверки | C1: Позиция | D1: Что не так | E1: Что делать
A2: 1 | B2: Цена ниже себестоимости | C2: — | D2: таких позиций нет: проверены все 60 строк каталога | E2: —
A3: 2 | B3: Маржа ниже 50% | C3: — | D3: после включения упаковки и подъёма цен таких позиций не осталось | E3: —
A4: 3 | B4: Цена поднята при сборке | C4: Первоклассник | D4: при цене 1590 ₽ и себестоимости с упаковкой 795,8 ₽ маржа была 49,9% (<50%) | E4: цена поднята до 1890 ₽ — маржа 57,9%
A5: 4 | B5: Цена поднята при сборке | C5: Луч | D5: при цене 1490 ₽ и себестоимости с упаковкой 839,4 ₽ маржа была 43,7% (<50%) | E5: цена поднята до 1990 ₽ — маржа 57,8%
A6: 5 | B6: Цена поднята при сборке | C6: Лиса | D6: при цене 1490 ₽ и себестоимости с упаковкой 840,0 ₽ маржа была 43,6% (<50%) | E6: цена поднята до 1990 ₽ — маржа 57,8%
A7: 6 | B7: Цена поднята из-за упаковки | C7: Солнце | D7: при цене 2790 ₽ и себестоимости с упаковкой 1529,1 ₽ маржа была 45,2% (<50%); позиция живая, в боте до сих пор стоит старая цена | E7: цена поднята до 3690 ₽ — маржа 58,6%; обновить через /edit
A8: 7 | B8: Цена поднята из-за упаковки | C8: Густой август | D8: при цене 3690 ₽ и себестоимости с упаковкой 1869,0 ₽ маржа была 49,3% (<50%); позиция живая, в боте до сих пор стоит старая цена | E8: цена поднята до 4490 ₽ — маржа 58,4%; обновить через /edit
A9: 8 | B9: Цена поднята из-за упаковки | C9: Эустома | D9: при цене 3290 ₽ и себестоимости с упаковкой 1958,9 ₽ маржа была 40,5% (<50%); позиция живая, в боте до сих пор стоит старая цена | E9: цена поднята до 4690 ₽ — маржа 58,2%; обновить через /edit
A10: 9 | B10: Цена поднята при сборке | C10: Сидр | D10: при цене 3290 ₽ и себестоимости с упаковкой 1759,7 ₽ маржа была 46,5% (<50%) | E10: цена поднята до 4190 ₽ — маржа 58,0%
A11: 10 | B11: Цена поднята при сборке | C11: Янтарь | D11: при цене 3890 ₽ и себестоимости с упаковкой 2009,3 ₽ маржа была 48,3% (<50%) | E11: цена поднята до 4790 ₽ — маржа 58,1%
A12: 11 | B12: Цена поднята при сборке | C12: Сливочный Крем | D12: при цене 3290 ₽ и себестоимости с упаковкой 2054,2 ₽ маржа была 37,6% (<50%) | E12: цена поднята до 4890 ₽ — маржа 58,0%
A13: 12 | B13: Цена поднята при сборке | C13: Жемчуг | D13: при цене 3490 ₽ и себестоимости с упаковкой 2089,5 ₽ маржа была 40,1% (<50%) | E13: цена поднята до 4990 ₽ — маржа 58,1%
... A58: 57 | B58: Статус позиций | C58: 46 новых (NEW-01…NEW-46) | D58: новых позиций нет в боте — они существуют только в этом файле | E58: заводить через /add по волнам (лист «План выкладки»)
